<?xml version="1.0" ?>
<!-- =================================================================================== -->
<!-- |    This document was autogenerated by xacro from puma560_robot.urdf.xacro       | -->
<!-- |    EDITING THIS FILE BY HAND IS NOT RECOMMENDED                                 | -->
<!-- =================================================================================== -->
<robot name="Perna_Mauricio" xmlns:xacro="http://www.ros.org/wiki/xacro">
    
  <material name="black">
    <color rgba="0.0 0.0 0.0 1.0"/>
  </material>
  <material name="blue">
    <color rgba="0.0 0.0 0.8 1.0"/>
  </material>
  <material name="green">
    <color rgba="0.0 0.8 0.0 1.0"/>
  </material>
  <material name="grey">
    <color rgba="0.2 0.2 0.2 1.0"/>
  </material>
  <material name="orange">
    <color rgba="1.0 0.423529411765 0.0392156862745 1.0"/>
  </material>
  <material name="brown">
    <color rgba="0.870588235294 0.811764705882 0.764705882353 1.0"/>
  </material>
  <material name="red">
    <color rgba="0.8 0.0 0.0 1.0"/>
  </material>
  <material name="white">
    <color rgba="1.0 1.0 1.0 1.0"/>
  </material>


<link name="base_link"/>
  <joint name="base_joint" type="fixed">
    <axis xyz="0 0 0"/>
    <origin rpy="0 0 0" xyz="0 0 .4 "/>
    <parent link="base_link"/>
    <child link="body"/>
  </joint>
    <link name="body">
	<inertial>
            <mass value="0.3" />
            <origin rpy="0 0 0" xyz="0 0 0.0" />
            <inertia ixx="0.0142175" ixy="-1.28579E-05" ixz="-2.31364E-05" iyy="0.0144041" iyz="1.93404E-05" izz="0.0104533" />
        </inertial>

        <visual>
      <origin
        xyz="0 0 0"
        rpy="0 0 0" />
      <geometry>
                <box size="0.15 0.25 0.15" />
      </geometry>
      <material
        name="">
        <color
          rgba="0.792156862745098 0.819607843137255 0.933333333333333 1" />
      </material>
    </visual>
        <collision>
            <origin rpy="0 0 0" xyz="0 0 0" />
            <geometry>
                <box size="0.15 0.25 0.15" />
                <!--mudei-->
            </geometry>
            <material name="">
                <color rgba="1 1 0 1" />
            </material>
        </collision>
    </link>

<link name="left_leg_top">
    <collision>
      <origin rpy="0 0 0" xyz="0 0.0 -0.105"/>
      <geometry>
        <box size="0.05 0.05 0.27" />
      </geometry>
    </collision>
    <visual>
      <origin rpy="0 0 0" xyz="0 0 -0.105"/>
      <geometry>
        <box size="0.05 0.05 0.27" />
      </geometry>
      <material name="grey"/>
    </visual>
    <inertial>
      <origin rpy="0 0 0 " xyz="0 0 -0.105"/>
      <mass value="0.02"/>
      <inertia ixx="0.00101081666667" ixy="0" ixz="0" iyy="0.00101081666667" iyz="0" izz="0.00196"/>
    </inertial>
  </link>
  
  <joint name="left_leg_top_joint" type="revolute">
    <parent link="body"/>
    <child link="left_leg_top"/>
    <origin rpy="0 0 0" xyz="-0.03 0.15 -0.075"/>
    <axis rpy="0 0 0" xyz="0 1 0"/>
    <limit command_effort="100" current="10" effort="80" gear_velocity="10" lower="-1.57" upper="1.57" velocity="15"/>   
    <joint_properties damping="0.0" friction="0.0"/>
  </joint>

<link name="right_leg_top">
    <collision>
      <origin rpy="0 0 0" xyz="0 0.0 -0.105"/>
      <geometry>
        <box size="0.05 0.05 0.27" />
      </geometry>
    </collision>
    <visual>
      <origin rpy="0 0 0" xyz="0 0 -0.105"/>
      <geometry>
        <box size="0.05 0.05 0.27" />
      </geometry>
      <material name="grey"/>
    </visual>
    <inertial>
      <origin rpy="0 0 0 " xyz="0 0 -0.105"/>
      <mass value="0.02"/>
      <inertia ixx="0.00101081666667" ixy="0" ixz="0" iyy="0.00101081666667" iyz="0" izz="0.00196"/>
    </inertial>
  </link>
  
  <joint name="right_leg_top_joint" type="revolute">
    <parent link="body"/>
    <child link="right_leg_top"/>
    <origin rpy="0 0 0" xyz="-0.03 -0.15 -0.075"/>
    <axis rpy="0 0 0" xyz="0 1 0"/>
    <limit command_effort="100" current="10" effort="80" gear_velocity="10" lower="-1.57" upper="1.57" velocity="15"/>   
    <joint_properties damping="0.0" friction="0.0"/>
  </joint>

<link name="left_leg_bottom">
    <collision>
      <origin rpy="0 0 0" xyz="0 0.0 -0.105"/>
      <geometry>
        <box size="0.05 0.05 0.27" />
      </geometry>
    </collision>
    <visual>
      <origin rpy="0 0 0" xyz="0 0 -0.105"/>
      <geometry>
        <box size="0.05 0.05 0.27" />
      </geometry>
      <material name="grey"/>
    </visual>
    <inertial>
      <origin rpy="0 0 0 " xyz="0 0 -0.105"/>
      <mass value="0.02"/>
      <inertia ixx="0.00101081666667" ixy="0" ixz="0" iyy="0.00101081666667" iyz="0" izz="0.00196"/>
    </inertial>
  </link>
  
  <joint name="left_leg_bottom_joint" type="revolute">
    <parent link="left_leg_top"/>
    <child link="left_leg_bottom"/>
    <origin rpy="0 0 0" xyz="0.0 -0.05 -0.2"/>
    <axis rpy="0 0 0" xyz="0 1 0"/>
    <limit command_effort="100" current="10" effort="80" gear_velocity="10" lower="-2.33" upper="0.78" velocity="15"/>   
    <joint_properties damping="0.0" friction="0.0"/>
  </joint>

<link name="right_leg_bottom">
    <collision>
      <origin rpy="0 0 0" xyz="0 0.0 -0.105"/>
      <geometry>
        <box size="0.05 0.05 0.27" />
      </geometry>
    </collision>
    <visual>
      <origin rpy="0 0 0" xyz="0 0 -0.105"/>
      <geometry>
        <box size="0.05 0.05 0.27" />
      </geometry>
      <material name="grey"/>
    </visual>
    <inertial>
      <origin rpy="0 0 0 " xyz="0 0 -0.105"/>
      <mass value="0.02"/>
      <inertia ixx="0.00101081666667" ixy="0" ixz="0" iyy="0.00101081666667" iyz="0" izz="0.00196"/>
    </inertial>
  </link>
  
  <joint name="right_leg_bottom_joint" type="revolute">
    <parent link="right_leg_top"/>
    <child link="right_leg_bottom"/>
    <origin rpy="0 0 0" xyz="0.0 0.05 -0.2"/>
    <axis rpy="0 0 0" xyz="0 1 0"/>
    <limit command_effort="100" current="10" effort="80" gear_velocity="10" lower="-2.33" upper="0.78" velocity="15"/>   
    <joint_properties damping="0.0" friction="0.0"/>
  </joint>

<link name="left_foot_bottom">
    <collision>
      <origin rpy="0 0 0" xyz="0 0.0 0"/>
      <geometry>
        <sphere radius="0.04" />
      </geometry>
    </collision>
    <visual>
      <origin rpy="0 0 0" xyz="0 0 0"/>
      <geometry>
        <sphere radius="0.04" />
      </geometry>
      <material name="white"/>
    </visual>
    <inertial>
      <origin rpy="0 0 0 " xyz="0 0 0"/>
      <mass value="0.02"/>
      <inertia ixx="0.00101081666667" ixy="0" ixz="0" iyy="0.00101081666667" iyz="0" izz="0.00196"/>
    </inertial>
  </link>
  
  <joint name="left_foot_joint" type="fixed">
    <axis xyz="0 0 0"/>
    <origin rpy="0 0 0" xyz="0 0 -0.23 "/>
    <parent link="left_leg_bottom"/>
    <child link="left_foot_bottom"/>
  </joint>
   

<link name="right_foot_bottom">
    <collision>
      <origin rpy="0 0 0" xyz="0 0.0 0"/>
      <geometry>
        <sphere radius="0.04" />
      </geometry>
    </collision>
    <visual>
      <origin rpy="0 0 0" xyz="0 0 0"/>
      <geometry>
        <sphere radius="0.04" />
      </geometry>
      <material name="white"/>
    </visual>
    <inertial>
      <origin rpy="0 0 0 " xyz="0 0 0"/>
      <mass value="0.02"/>
      <inertia ixx="0.00101081666667" ixy="0" ixz="0" iyy="0.00101081666667" iyz="0" izz="0.00196"/>
    </inertial>
  </link>
  
  <joint name="right_foot_joint" type="fixed">
    <axis xyz="0 0 0"/>
    <origin rpy="0 0 0" xyz="0 0 -0.23 "/>
    <parent link="right_leg_bottom"/>
    <child link="right_foot_bottom"/>
  </joint>
    <!-- end of link list -->
    <!-- joint list -->
    
    

</robot>


